Workbook

Sheet Пояснения
B2: Расчётная модель ГКМ «Северное сияние» — версия 4 (25.10.2026)
B3: Кейс-чемпионат газовой отрасли. Все стоимостные показатели — реальные цены 2026 г., млрд руб. без НДС; горизонт 2027–2066 гг.
B5: Назначение | C5: Технико-экономическая оценка освоения ГКМ «Северное сияние» (НГЗ 320 млрд м³) и сравнение вариантов подготовки газа; выбор решения команды — НТС на ТДА + GTL-установка 40 тыс. т ДТ и 30 тыс. т авиакеросина в год для внутренних нужд кластера.
B6: Главный результат | C6: ="NPV нашего варианта при реальной ставке 10 %: "&TEXT(Расчёт_Наш!C5,"0.0")&" млрд руб; IRR "&TEXT(Расчёт_Наш!C6,"0.0%")&"; CAPEX "&TEXT(Расчёт_Наш!C9,"0")&" млрд руб; окупаемость (дисконт.) — "&Расчёт_Наш!C7&" г." -> NPV нашего варианта при реальной ставке 10 %: 22.5 млрд руб; IRR 11.0%; CAPEX 362 млрд руб; окупаемость (дисконт.) — 2048 г.
B7: Структура | C7: «Исходные» — общие данные с источниками; «Баланс» — выход продуктов на 1000 м³ по технологиям; «CAPEX_нормы» — состав и график объектов; «Сценарии» — параметры вариантов; «Расчёт_…» — профиль добычи, продукция, выручка, налоги, CAPEX, FCF и NPV по годам; «Сравнение» — сводка; «Чувствительность» — как достигнута прибыльность, полки, торнадо, пороги; «Источники».
B8: Варианты | C8: А — НТС + стабилизация; Б — ТДА + ГФУ (СУГ); В — Б + этан; Г — НТС на ТДА без GTL; Наш выбор — Г + GTL 40+30. Стресс-сценарии нашего варианта: дебит 0,55; цены GTL команды 40 000 / 47 500; без льготы Кр.
B9: Что изменилось в v4 | C9: GTL уменьшен до 40 + 30 тыс. т/год (внутренние нужды); скважина 1,5 млрд руб; ВЖК у УКПГ возвращён (4 млрд руб); горизонтальные скважины 0,75 млн м³/сут; полка 12 млрд м³/год; учтён Кр (п-ов Ямал) в НДПИ; продукты GTL оценены по трансфертной цене (80 % биржи без НДС).
B10: Как пользоваться | C10: Меняйте синие ячейки на листах «Исходные» и «Сценарии» — все расчёты пересчитываются формулами. Если меняете полку добычи, подберите темп падения (строка «Темп падения» на «Сценарии») так, чтобы проверка на листе расчёта (C11) была ≈ 0.
B11: Цвета | C11: Синий шрифт — ввод; чёрный — формулы; зелёный — ссылки на другие листы; жёлтая заливка — ключевые решения команды.
B12: Методика | C12: Реальные цены 2026 г. без НДС; дисконтирование на середину года к началу 2027 г.; амортизация линейная 15 лет; налог на имущество 2,2 % от остаточной стоимости; налог на прибыль 25 % без переноса убытков (консервативно).
B13: Ограничения | C13: Базовая часть НДПИ, OPEX и часть CAPEX — оценки команды; будут уточнены при дальнейших расчётах. Экспортный нетбэк для «Силы Сибири — 2» в модели не учитывается — газ продаётся в ЕСГ по цене ФАС.

Sheet Сравнение
B2: Сравнение вариантов и сценариев
B3: Все значения — формулы-ссылки на листы «Расчёт_…». Изменяйте параметры на листе «Сценарии».
B5: Показатель | C5: А. НТС + стабилизация | D5: Б. ТДА + ГФУ (СУГ) | E5: В. Б + этан | F5: Г. НТС на ТДА, без GTL | G5: Наш выбор: ТДА + GTL 40+30 | H5: Наш выбор — дебит 0,55 | I5: Наш выбор — цены ДТ/керосина 40 000/47 500 | J5: Наш выбор — без коэффициента Кр
B6: ЧДД (NPV), млрд руб | C6: =Расчёт_А!C5 -> 15.105132 | D6: =Расчёт_Б!C5 -> -9.3797347 | E6: =Расчёт_В!C5 -> -75.259733 | F6: =Расчёт_Г!C5 -> 16.893083 | G6: =Расчёт_Наш!C5 -> 22.511796 | H6: =Расчёт_Наш_дебит!C5 -> -1.5517793 | I6: =Расчёт_Наш_цены!C5 -> 17.588383 | J6: =Расчёт_Наш_безКр!C5 -> 13.729305
B7: ВНД (IRR) | C7: =Расчёт_А!C6 -> 0.10741094 | D7: =Расчёт_Б!C6 -> 0.096053345 | E7: =Расчёт_В!C6 -> 0.071124893 | F7: =Расчёт_Г!C6 -> 0.10816471 | G7: =Расчёт_Наш!C6 -> 0.11044479 | H7: =Расчёт_Наш_дебит!C6 -> 0.099321669 | I7: =Расчёт_Наш_цены!C6 -> 0.10824739 | J7: =Расчёт_Наш_безКр!C6 -> 0.10632689
B8: Дисконтированная окупаемость, год | C8: =Расчёт_А!C7 -> 2050 | D8: =Расчёт_Б!C7 -> нет | E8: =Расчёт_В!C7 -> нет | F8: =Расчёт_Г!C7 -> 2049 | G8: =Расчёт_Наш!C7 -> 2048 | H8: =Расчёт_Наш_дебит!C7 -> нет | I8: =Расчёт_Наш_цены!C7 -> 2049 | J8: =Расчёт_Наш_безКр!C7 -> 2051
B9: Индекс доходности (PI) | C9: =Расчёт_А!C8 -> 1.0613708 | D9: =Расчёт_Б!C8 -> 0.96857102 | E9: =Расчёт_В!C8 -> 0.78210017 | F9: =Расчёт_Г!C8 -> 1.0677063 | G9: =Расчёт_Наш!C8 -> 1.0878941 | H9: =Расчёт_Наш_дебит!C8 -> 0.99442881 | I9: =Расчёт_Наш_цены!C8 -> 1.0686713 | J9: =Расчёт_Наш_безКр!C8 -> 1.0536041
B10: CAPEX всего, млрд руб | C10: =Расчёт_А!C9 -> 347.05583 | D10: =Расчёт_Б!C9 -> 423.0023 | E10: =Расчёт_В!C9 -> 485.84218 | F10: =Расчёт_Г!C9 -> 351.54439 | G10: =Расчёт_Наш!C9 -> 362.29439 | H10: =Расчёт_Наш_дебит!C9 -> 393.46322 | I10: =Расчёт_Наш_цены!C9 -> 362.29439 | J10: =Расчёт_Наш_безКр!C9 -> 362.29439
B11: Фонд скважин, шт. | C11: =Расчёт_А!C10 -> 57.142857 | D11: =Расчёт_Б!C10 -> 57.142857 | E11: =Расчёт_В!C10 -> 57.142857 | F11: =Расчёт_Г!C10 -> 57.142857 | G11: =Расчёт_Наш!C10 -> 57.142857 | H11: =Расчёт_Наш_дебит!C10 -> 77.922078 | I11: =Расчёт_Наш_цены!C10 -> 57.142857 | J11: =Расчёт_Наш_безКр!C10 -> 57.142857
B13: Добыча газа за период, млрд м³ | C13: =Расчёт_А!D52 -> 275.20035 | D13: =Расчёт_Б!D52 -> 275.20035 | E13: =Расчёт_В!D52 -> 275.20035 | F13: =Расчёт_Г!D52 -> 275.20035 | G13: =Расчёт_Наш!D52 -> 275.20035 | H13: =Расчёт_Наш_дебит!D52 -> 275.20035 | I13: =Расчёт_Наш_цены!D52 -> 275.20035 | J13: =Расчёт_Наш_безКр!D52 -> 275.20035
B14: Товарный газ, млрд м³ | C14: =Расчёт_А!D60 -> 263.95723 | D14: =Расчёт_Б!D60 -> 254.75682 | E14: =Расчёт_В!D60 -> 241.57984 | F14: =Расчёт_Г!D60 -> 263.57572 | G14: =Расчёт_Наш!D60 -> 257.23159 | H14: =Расчёт_Наш_дебит!D60 -> 257.23159 | I14: =Расчёт_Наш_цены!D60 -> 257.23159 | J14: =Расчёт_Наш_безКр!D60 -> 257.23159
B15: Конденсат + нафта, млн т | C15: =Расчёт_А!D61 -> 9.9518493 | D15: =Расчёт_Б!D61 -> 8.7840914 | E15: =Расчёт_В!D61 -> 8.8284555 | F15: =Расчёт_Г!D61 -> 11.022304 | G15: =Расчёт_Наш!D61 -> 11.022304 | H15: =Расчёт_Наш_дебит!D61 -> 11.022304 | I15: =Расчёт_Наш_цены!D61 -> 11.022304 | J15: =Расчёт_Наш_безКр!D61 -> 11.022304
B16: СУГ, млн т | C16: =Расчёт_А!D62 -> 0 | D16: =Расчёт_Б!D62 -> 19.457821 | E16: =Расчёт_В!D62 -> 20.760515 | F16: =Расчёт_Г!D62 -> 0 | G16: =Расчёт_Наш!D62 -> 0 | H16: =Расчёт_Наш_дебит!D62 -> 0 | I16: =Расчёт_Наш_цены!D62 -> 0 | J16: =Расчёт_Наш_безКр!D62 -> 0
B17: ДТ GTL, млн т | C17: =Расчёт_А!D64 -> 0 | D17: =Расчёт_Б!D64 -> 0 | E17: =Расчёт_В!D64 -> 0 | F17: =Расчёт_Г!D64 -> 0 | G17: =Расчёт_Наш!D64 -> 1.36 | H17: =Расчёт_Наш_дебит!D64 -> 1.36 | I17: =Расчёт_Наш_цены!D64 -> 1.36 | J17: =Расчёт_Наш_безКр!D64 -> 1.36
B18: Керосин GTL, млн т | C18: =Расчёт_А!D65 -> 0 | D18: =Расчёт_Б!D65 -> 0 | E18: =Расчёт_В!D65 -> 0 | F18: =Расчёт_Г!D65 -> 0 | G18: =Расчёт_Наш!D65 -> 1.02 | H18: =Расчёт_Наш_дебит!D65 -> 1.02 | I18: =Расчёт_Наш_цены!D65 -> 1.02 | J18: =Расчёт_Наш_безКр!D65 -> 1.02
B19: Выручка, млрд руб | C19: =Расчёт_А!D73 -> 1749.8583 | D19: =Расчёт_Б!D73 -> 1975.2311 | E19: =Расчёт_В!D73 -> 1888.5832 | F19: =Расчёт_Г!D73 -> 1782.93 | G19: =Расчёт_Наш!D73 -> 1900.2813 | H19: =Расчёт_Наш_дебит!D73 -> 1900.2813 | I19: =Расчёт_Наш_цены!D73 -> 1861.0453 | J19: =Расчёт_Наш_безКр!D73 -> 1900.2813
B20: НДПИ, млрд руб | C20: =Расчёт_А!D74 -> 234.56078 | D20: =Расчёт_Б!D74 -> 269.73584 | E20: =Расчёт_В!D74 -> 263.62312 | F20: =Расчёт_Г!D74 -> 239.12514 | G20: =Расчёт_Наш!D74 -> 240.23307 | H20: =Расчёт_Наш_дебит!D74 -> 240.23307 | I20: =Расчёт_Наш_цены!D74 -> 240.23307 | J20: =Расчёт_Наш_безКр!D74 -> 265.41494
B21: OPEX, млрд руб | C21: =Расчёт_А!D97 -> 225.79578 | D21: =Расчёт_Б!D97 -> 294.27861 | E21: =Расчёт_В!D97 -> 330.18836 | F21: =Расчёт_Г!D97 -> 228.75483 | G21: =Расчёт_Наш!D97 -> 248.83412 | H21: =Расчёт_Наш_дебит!D97 -> 265.30061 | I21: =Расчёт_Наш_цены!D97 -> 248.83412 | J21: =Расчёт_Наш_безКр!D97 -> 248.83412
B22: Налог на прибыль, млрд руб | C22: =Расчёт_А!D103 -> 223.03102 | D22: =Расчёт_Б!D103 -> 232.40299 | E22: =Расчёт_В!D103 -> 187.09147 | F22: =Расчёт_Г!D103 -> 228.11384 | G22: =Расчёт_Наш!D103 -> 249.03413 | H22: =Расчёт_Наш_дебит!D103 -> 236.55117 | I22: =Расчёт_Наш_цены!D103 -> 239.22513 | J22: =Расчёт_Наш_безКр!D103 -> 243.14004
B23: FCF недисконтированный, млрд руб | C23: =Расчёт_А!D105 -> 664.50494 | D23: =Расчёт_Б!D105 -> 688.96865 | E23: =Расчёт_В!D105 -> 545.31799 | F23: =Расчёт_Г!D105 -> 679.79063 | G23: =Расчёт_Наш!D105 -> 742.39239 | H23: =Расчёт_Наш_дебит!D105 -> 702.30289 | I23: =Расчёт_Наш_цены!D105 -> 712.96539 | J23: =Расчёт_Наш_безКр!D105 -> 723.10461
B25: Разница NPV с нашим базовым вариантом, млрд руб | C25: =C6-$G$6 -> -7.4066643 | D25: =D6-$G$6 -> -31.891531 | E25: =E6-$G$6 -> -97.771529 | F25: =F6-$G$6 -> -5.6187134 | G25: =G6-$G$6 -> 0 | H25: =H6-$G$6 -> -24.063576 | I25: =I6-$G$6 -> -4.9234132 | J25: =J6-$G$6 -> -8.7824914
B27: Вывод
B28: =IF(G6>0,"Наш вариант (ТДА + GTL 40+30) прибылен: NPV = "&TEXT(G6,"0.0")&" млрд руб, IRR = "&TEXT(G7,"0.0%")&" — лучший среди вариантов А–Г.","Наш вариант пока не окупается при ставке сценария.") -> Наш вариант (ТДА + GTL 40+30) прибылен: NPV = 22.5 млрд руб, IRR = 11.0% — лучший среди вариантов А–Г.

Sheet Исходные
B2: Исходные данные и допущения, общие для всех вариантов
B3: Синий шрифт — вводимые значения, чёрный — формулы, зелёный — ссылки. Источник и дата указаны для каждой строки.
B5: Параметр | C5: Значение | D5: Ед. | E5: Источник / обоснование | F5: Дата
B6: Начальные запасы газа (НГЗ) | C6: 320 | D6: млрд м³ | E6: Задание кейса | F6: 2026
B7: Коэффициент извлечения газа (КИГ) | C7: 0.86 | D7: д. ед. | E7: Задание кейса | F7: 2026
B8: Извлекаемые запасы | C8: =C6*C7 -> 275.2 | D8: млрд м³ | E8: НГЗ × КИГ
B9: Первый год добычи | C9: 2031 | D9: год | E9: Допущение команды: 2027 — доразведка и ПД, 2028–2030 — строительство
B10: Отбор до начала падения добычи | C10: 0.56 | D10: доля извл. | E10: Допущение: полка до отбора 56 % извлекаемых запасов (типично для ГКМ Ямала)
B11: Молярный объём газа | C11: 24.055 | D11: м³/кмоль | E11: ГОСТ 2939-63: стандартные условия 20 °C, 101,325 кПа
B12: Базисная теплота сгорания для цены ФАС | C12: 33.07572 | D12: МДж/м³ | E12: 7900 ккал/м³ × 4,1868 — базис оптовых цен ФАС
B13: Оптовая цена газа, ЯНАО (база) | C13: 4705 | D13: руб/1000 м³ | E13: Приказ ФАС № 1213/25: среднее мин./макс. для ЯНАО — https://pravo.ppt.ru/prikaz/fas/n-1213-25-326387 | F13: 2025
B14: Brent (база) | C14: 65 | D14: $/барр. | E14: Котировки октября 2026 — https://index.minfin.com.ua/markets/oil/2026-10/ | F14: 10.2026
B15: Курс | C15: 85 | D15: руб/$ | E15: Допущение на уровне октября 2026 | F15: 10.2026
B16: Дисконт конденсата к Brent | C16: 3 | D16: $/барр. | E16: Допущение
B17: Баррелей в тонне конденсата | C17: 8.8 | D17: барр./т | E17: Справочно для лёгкого конденсата
B18: Логистика конденсата до порта | C18: 9000 | D18: руб/т | E18: Допущение: конденсатопровод → ж/д Обская–Бованенково → Усть-Луга, перевалка
B19: Цена СУГ (нетбэк на промысле) | C19: 20000 | D19: руб/т | E19: Допущение (консервативно)
B20: Цена этана (нетбэк) | C20: 0 | D20: руб/т | E20: Нет потребителя этана в регионе — 0
B21: Собственные нужды до ДКС | C21: 0.02 | D21: доля | E21: Допущение
B22: Собственные нужды после ввода ДКС (с 2038 г.) | C22: 0.035 | D22: доля | E22: Допущение
B23: НДПИ газ: показатель Ккг (Газпром) | C23: 494 | D23: руб/1000 м³ | E23: С 01.10.2026 — https://www.interfax.ru/business/1056714 | F23: 10.2026
B24: НДПИ газ: базовая часть (35×Еут×Кс + Тг) до Кр | C24: 250 | D24: руб/1000 м³ | E24: Оценка команды; будет уточнена при дальнейших расчётах
B25: НДПИ жидких УВ, доля от нетбэка (до Кр) | C25: 0.15 | D25: доля | E25: Упрощённая оценка
B26: Кр (п-ов Ямал): коэффициент при n | C26: 0.066 | E26: НК РФ ст. 342.4 п. 9: Кр = 0,066 × n + 0,144 на 144 налоговых периода — https://pravo.ppt.ru/kodeks/nk/st-342.4 | F26: 10.2026
B27: Кр (п-ов Ямал): свободный член | C27: 0.144 | E27: То же | F27: 10.2026
B28: Срок действия Кр | C28: 12 | D28: лет | E28: 144 месяца с года, когда выработанность впервые > 1 %
B29: Порог выработанности для старта Кр | C29: 0.01 | D29: доля НГЗ | E29: НК РФ ст. 342.4 п. 9
B30: Налог на прибыль | C30: 0.25 | D30: доля | E30: НК РФ с 2025 г. — 25 % | F30: 2025
B31: Налог на имущество | C31: 0.022 | D31: доля/год | E31: Ставка 2,2 % от остаточной стоимости
B32: Срок амортизации | C32: 15 | D32: лет | E32: Линейно, с года ввода (капвложения до 2031 г. — с 2031 г.)
B33: Постоянные OPEX | C33: 0.015 | D33: доля накопл. CAPEX/год | E33: Допущение; включает содержание ВЖК у УКПГ
B34: Переменные OPEX | C34: 150 | D34: руб/1000 м³ сырого газа | E34: Допущение
B35: OPEX по СУГ | C35: 1000 | D35: руб/т | E35: Допущение
B36: Тариф терминала / перевалки жидких УВ | C36: 500 | D36: руб/т | E36: Допущение
B37: GTL: выход синтетических УВ | C37: 0.41 | D37: т/1000 м³ | E37: INFRA Technology: 390–440 кг на 1000 м³ — https://ru.infratechnology.ru/technology/ | F37: 10.2026
B38: GTL: доля ДТ + керосина в синтетических УВ | C38: 0.915 | D38: доля | E38: Допущение; остаток — нафта, сдаётся с конденсатом
B39: GTL: выпуск ДТ | C39: 40 | D39: тыс. т/год | E39: Решение команды (внутренние нужды кластера) | F39: 25.10.2026
B40: GTL: выпуск авиакеросина | C40: 30 | D40: тыс. т/год | E40: Решение команды (внутренние нужды кластера) | F40: 25.10.2026
B41: GTL: OPEX | C41: 5525 | D41: руб/т синт. УВ | E41: INFRA: $35–65/т × 85 руб/$ (верх диапазона) | F41: 10.2026
B42: GTL: первый год работы | C42: 2033 | D42: год | E42: Строительство 2031–2032
...

Sheet Баланс
B2: Материальный баланс на 1000 м³ сырого газа по технологиям
B3: Состав газа — задание кейса (сумма 99,95 % нормируется). Степени извлечения — допущения по типовым технологиям.
B5: Компонент | C5: Мол. % | D5: M, кг/кмоль | E5: Qн, МДж/м³ | F5: Извл. A | G5: Извл. B | H5: Извл. T | I5: Извл. C
B6: C1 | C6: 88.5 | D6: 16.043 | E6: 33.4101 | F6: 0 | G6: 0 | H6: 0 | I6: 0
B7: C2 | C7: 5.5 | D7: 30.069 | E7: 59.458 | F7: 0 | G7: 0 | H7: 0 | I7: 0.85
B8: C3 | C8: 3 | D8: 44.096 | E8: 85.0243 | F8: 0 | G8: 0.9 | H8: 0 | I8: 0.98
B9: iC4 | C9: 0.45 | D9: 58.122 | E9: 110.1876 | F9: 0.25 | G9: 0.97 | H9: 0.35 | I9: 0.99
B10: nC4 | C10: 0.55 | D10: 58.122 | E10: 110.5808 | F10: 0.3 | G10: 0.97 | H10: 0.42 | I10: 0.99
B11: C5+ | C11: 0.8 | D11: 100 | E11: 188.233 | F11: 0.92 | G11: 0.99 | H11: 0.96 | I11: 0.995
B12: N2 | C12: 0.5 | D12: 28.013 | E12: 0 | F12: 0 | G12: 0 | H12: 0 | I12: 0
B13: CO2 | C13: 0.65 | D13: 44.01 | E13: 0 | F13: 0 | G13: 0 | H13: 0 | I13: 0
B14: Сумма | C14: =SUM(C6:C13) -> 99.95
B15: Количество кмоль в 1000 м³ | C15: =1000/Исходные!$C$11 -> 41.571399
B17: Продукт, на 1000 м³ сырого газа | C17: Ед. | D17: A | E17: B | F17: T | G17: C
B18: Стабильный конденсат (C5+, для A и T — с частью C4) | C18: кг | D18: =$C$11/$C$14*$C$15*$D$11*F$11+($C$9/$C$14*$C$15*$D$9*F$9+$C$10/$C$14*$C$15*$D$10*F$10) -> 37.3202 | E18: =$C$11/$C$14*$C$15*$D$11*G$11 -> 32.941018 | F18: =$C$11/$C$14*$C$15*$D$11*H$11+($C$9/$C$14*$C$15*$D$9*H$9+$C$10/$C$14*$C$15*$D$10*H$10) -> 41.334488 | G18: =$C$11/$C$14*$C$15*$D$11*I$11 -> 33.107387
B19: СПБТ (C3 + C4) | C19: кг | D19: 0 | E19: =$C$8/$C$14*$C$15*$D$8*G$8+($C$9/$C$14*$C$15*$D$9*G$9+$C$10/$C$14*$C$15*$D$10*G$10) -> 72.968324 | F19: 0 | G19: =$C$8/$C$14*$C$15*$D$8*I$8+($C$9/$C$14*$C$15*$D$9*I$9+$C$10/$C$14*$C$15*$D$10*I$10) -> 77.853527
B20: Этан | C20: кг | D20: =$C$7/$C$14*$C$15*$D$7*F$7 -> 0 | E20: =$C$7/$C$14*$C$15*$D$7*G$7 -> 0 | F20: =$C$7/$C$14*$C$15*$D$7*H$7 -> 0 | G20: =$C$7/$C$14*$C$15*$D$7*I$7 -> 58.467219
B21: Товарный газ, объём | C21: м³ | D21: =SUMPRODUCT($C$6:$C$13,1-F$6:F$13)/$C$14*1000 -> 989.85993 | E21: =SUMPRODUCT($C$6:$C$13,1-G$6:G$13)/$C$14*1000 -> 955.35768 | F21: =SUMPRODUCT($C$6:$C$13,1-H$6:H$13)/$C$14*1000 -> 988.42921 | G21: =SUMPRODUCT($C$6:$C$13,1-I$6:I$13)/$C$14*1000 -> 905.94297
B22: Теплота сгорания товарного газа | C22: МДж/м³ | D22: =SUMPRODUCT($C$6:$C$13,1-F$6:F$13,$E$6:$E$13)/SUMPRODUCT($C$6:$C$13,1-F$6:F$13) -> 36.697221 | E22: =SUMPRODUCT($C$6:$C$13,1-G$6:G$13,$E$6:$E$13)/SUMPRODUCT($C$6:$C$13,1-G$6:G$13) -> 34.707378 | F22: =SUMPRODUCT($C$6:$C$13,1-H$6:H$13,$E$6:$E$13)/SUMPRODUCT($C$6:$C$13,1-H$6:H$13) -> 36.565304 | G22: =SUMPRODUCT($C$6:$C$13,1-I$6:I$13,$E$6:$E$13)/SUMPRODUCT($C$6:$C$13,1-I$6:I$13) -> 33.272649
B24: A — НТС (−30 °C) + стабилизация; B — ТДА (−60…−70 °C) + ГФУ (СУГ); T — НТС на ТДА (−35…−40 °C) + стабилизация (наш выбор); C — B + криогенное извлечение этана.

Sheet CAPEX_нормы
B2: Нормативы капитальных вложений (при полке 14 млрд м³/год) и график освоения
B3: Масштаб «да» — × (полка / 14)^0,7; «нет» — фиксированная сумма; «скв» — число скважин × стоимость скважины. Флаги показывают, в каких вариантах есть объект.
B5: Объект | C5: Сумма, млрд руб | D5: Масштаб | E5: A | F5: B | G5: C | H5: T0 | I5: T | J5: 2027 | K5: 2028 | L5: 2029 | M5: 2030 | N5: 2031 | O5: 2032 | P5: 2033 | Q5: 2034 | R5: 2035 | S5: 2036 | T5: 2037 | U5: 2038 | V5: 2039 | W5: 2040 | X5: 2041 | Y5: 2042 | Z5: 2043 | AA5: 2044 | AB5: 2045 | AC5: Σ долей | AD5: Обоснование
B6: Доразведка, 3D, ТЭО и проектная документация | C6: 15 | D6: нет | E6: 1 | F6: 1 | G6: 1 | H6: 1 | I6: 1 | J6: 1 | K6: 0 | L6: 0 | M6: 0 | N6: 0 | O6: 0 | P6: 0 | Q6: 0 | R6: 0 | S6: 0 | T6: 0 | U6: 0 | V6: 0 | W6: 0 | X6: 0 | Y6: 0 | Z6: 0 | AA6: 0 | AB6: 0 | AC6: =SUM(J6:AB6) -> 1 | AD6: Оценка команды: 3D-сейсмика, разведочные скважины, ТЭО, ПД
B7: Эксплуатационные скважины | C7: — | D7: скв | E7: 1 | F7: 1 | G7: 1 | H7: 1 | I7: 1 | J7: 0 | K7: 0.2 | L7: 0.3 | M7: 0.3 | N7: 0.08 | O7: 0 | P7: 0 | Q7: 0 | R7: 0 | S7: 0.03 | T7: 0.03 | U7: 0.03 | V7: 0.03 | W7: 0 | X7: 0 | Y7: 0 | Z7: 0 | AA7: 0 | AB7: 0 | AC7: =SUM(J7:AB7) -> 1 | AD7: Стоимость скважины — решение команды 1,5 млрд руб (лист «Сценарии»)
B8: Кусты скважин и газосборная сеть | C8: 46.5 | D8: да | E8: 1 | F8: 1 | G8: 1 | H8: 1 | I8: 1 | J8: 0 | K8: 0.3 | L8: 0.4 | M8: 0.3 | N8: 0 | O8: 0 | P8: 0 | Q8: 0 | R8: 0 | S8: 0 | T8: 0 | U8: 0 | V8: 0 | W8: 0 | X8: 0 | Y8: 0 | Z8: 0 | AA8: 0 | AB8: 0 | AC8: =SUM(J8:AB8) -> 1 | AD8: 50 млрд × 0,93 (снижение металлоёмкости эстакад — материалы кейса)
B9: УКПГ: НТС, регенерация метанола, стабилизация | C9: 78.12 | D9: да | E9: 1 | F9: 1 | G9: 1 | H9: 1 | I9: 1 | J9: 0 | K9: 0.297619 | L9: 0.416667 | M9: 0.285714 | N9: 0 | O9: 0 | P9: 0 | Q9: 0 | R9: 0 | S9: 0 | T9: 0 | U9: 0 | V9: 0 | W9: 0 | X9: 0 | Y9: 0 | Z9: 0 | AA9: 0 | AB9: 0 | AC9: =SUM(J9:AB9) -> 1 | AD9: 84 млрд × 0,93 (то же)
B10: Турбодетандерные агрегаты (5 шт.) | C10: 5 | D10: да | E10: 0 | F10: 0 | G10: 0 | H10: 1 | I10: 1 | J10: 0 | K10: 0 | L10: 0.5 | M10: 0.5 | N10: 0 | O10: 0 | P10: 0 | Q10: 0 | R10: 0 | S10: 0 | T10: 0 | U10: 0 | V10: 0 | W10: 0 | X10: 0 | Y10: 0 | Z10: 0 | AA10: 0 | AB10: 0 | AC10: =SUM(J10:AB10) -> 1 | AD10: 5 ТДА (4 раб. + 1 рез.) по 8,4 млн м³/сут — оценка
B11: ТДА + деэтанизация + ГФУ + парк СУГ | C11: 60 | D11: да | E11: 0 | F11: 1 | G11: 1 | H11: 0 | I11: 0 | J11: 0 | K11: 0 | L11: 0.416667 | M11: 0.583333 | N11: 0 | O11: 0 | P11: 0 | Q11: 0 | R11: 0 | S11: 0 | T11: 0 | U11: 0 | V11: 0 | W11: 0 | X11: 0 | Y11: 0 | Z11: 0 | AA11: 0 | AB11: 0 | AC11: =SUM(J11:AB11) -> 1 | AD11: Оценка для варианта B
B12: Продуктопровод СУГ 120 км | C12: 9.6 | D12: да | E12: 0 | F12: 1 | G12: 1 | H12: 0 | I12: 0 | J12: 0 | K12: 0 | L12: 0.520833 | M12: 0.479167 | N12: 0 | O12: 0 | P12: 0 | Q12: 0 | R12: 0 | S12: 0 | T12: 0 | U12: 0 | V12: 0 | W12: 0 | X12: 0 | Y12: 0 | Z12: 0 | AA12: 0 | AB12: 0 | AC12: =SUM(J12:AB12) -> 1 | AD12: Оценка для вариантов B, C
B13: Налив СУГ на ж/д | C13: 3 | D13: да | E13: 0 | F13: 1 | G13: 1 | H13: 0 | I13: 0 | J13: 0 | K13: 0 | L13: 0.5 | M13: 0.5 | N13: 0 | O13: 0 | P13: 0 | Q13: 0 | R13: 0 | S13: 0 | T13: 0 | U13: 0 | V13: 0 | W13: 0 | X13: 0 | Y13: 0 | Z13: 0 | AA13: 0 | AB13: 0 | AC13: =SUM(J13:AB13) -> 1 | AD13: Оценка для вариантов B, C
B14: Пропановая холодильная установка | C14: 12 | D14: да | E14: 0 | F14: 1 | G14: 1 | H14: 0 | I14: 0 | J14: 0 | K14: 0 | L14: 0 | M14: 0 | N14: 0 | O14: 0 | P14: 0 | Q14: 0 | R14: 0 | S14: 0 | T14: 0 | U14: 1 | V14: 0 | W14: 0 | X14: 0 | Y14: 0 | Z14: 0 | AA14: 0 | AB14: 0 | AC14: =SUM(J14:AB14) -> 1 | AD14: Оценка: поддержание −60 °C при падении давления
B15: Криогенный блок извлечения этана | C15: 70 | D15: да | E15: 0 | F15: 0 | G15: 1 | H15: 0 | I15: 0 | J15: 0 | K15: 0 | L15: 0.428571 | M15: 0.571429 | N15: 0 | O15: 0 | P15: 0 | Q15: 0 | R15: 0 | S15: 0 | T15: 0 | U15: 0 | V15: 0 | W15: 0 | X15: 0 | Y15: 0 | Z15: 0 | AA15: 0 | AB15: 0 | AC15: =SUM(J15:AB15) -> 1 | AD15: Оценка для варианта C
B16: Энергоцентр (ЭСН), промбаза | C16: 12 | D16: да | E16: 1 | F16: 1 | G16: 1 | H16: 1 | I16: 1 | J16: 0 | K16: 0.416667 | L16: 0.416667 | M16: 0.166667 | N16: 0 | O16: 0 | P16: 0 | Q16: 0 | R16: 0 | S16: 0 | T16: 0 | U16: 0 | V16: 0 | W16: 0 | X16: 0 | Y16: 0 | Z16: 0 | AA16: 0 | AB16: 0 | AC16: =SUM(J16:AB16) -> 1.000001 | AD16: Оценка; ВЖК вынесен отдельной строкой
B17: Вахтовый жилой комплекс у УКПГ | C17: — | D17: нет | E17: 1 | F17: 1 | G17: 1 | H17: 1 | I17: 1 | J17: 0 | K17: 0.375 | L17: 0.375 | M17: 0.25 | N17: 0 | O17: 0 | P17: 0 | Q17: 0 | R17: 0 | S17: 0 | T17: 0 | U17: 0 | V17: 0 | W17: 0 | X17: 0 | Y17: 0 | Z17: 0 | AA17: 0 | AB17: 0 | AC17: =SUM(J17:AB17) -> 1 | AD17: Оценка ≈20 млн руб/место × 200 мест (аналог: ВЖК Семаковского, 200 мест — https://neftegas.info/news/article/20669)
B18: Автодорога до Бованенково 120 км | C18: — | D18: нет | E18: 1 | F18: 1 | G18: 1 | H18: 1 | I18: 1 | J18: 0 | K18: 0.4 | L18: 0.4 | M18: 0.2 | N18: 0 | O18: 0 | P18: 0 | Q18: 0 | R18: 0 | S18: 0 | T18: 0 | U18: 0 | V18: 0 | W18: 0 | X18: 0 | Y18: 0 | Z18: 0 | AA18: 0 | AB18: 0 | AC18: =SUM(J18:AB18) -> 1 | AD18: 120 км × 0,20 млрд руб/км (ЯНАО: $2,4–2,5 млн/км — goarctic.ru, Минтранс)
B19: Газопровод 120 км до Бованенково | C19: 42 | D19: да | E19: 1 | F19: 1 | G19: 1 | H19: 1 | I19: 1 | J19: 0 | K19: 0.285714 | L19: 0.47619 | M19: 0.238095 | N19: 0 | O19: 0 | P19: 0 | Q19: 0 | R19: 0 | S19: 0 | T19: 0 | U19: 0 | V19: 0 | W19: 0 | X19: 0 | Y19: 0 | Z19: 0 | AA19: 0 | AB19: 0 | AC19: =SUM(J19:AB19) -> 0.999999 | AD19: Оценка 120 км до врезки в «Бованенково — Ухта»
B20: Конденсатопровод 120 км | C20: 9.6 | D20: да | E20: 1 | F20: 1 | G20: 1 | H20: 1 | I20: 1 | J20: 0 | K20: 0 | L20: 0.625 | M20: 0.375 | N20: 0 | O20: 0 | P20: 0 | Q20: 0 | R20: 0 | S20: 0 | T20: 0 | U20: 0 | V20: 0 | W20: 0 | X20: 0 | Y20: 0 | Z20: 0 | AA20: 0 | AB20: 0 | AC20: =SUM(J20:AB20) -> 1 | AD20: Оценка 120 км до ст. Бованенково
B21: ДКС (2 очереди) | C21: 55 | D21: да | E21: 1 | F21: 1 | G21: 1 | H21: 1 | I21: 1 | J21: 0 | K21: 0 | L21: 0 | M21: 0 | N21: 0 | O21: 0 | P21: 0 | Q21: 0 | R21: 0 | S21: 0 | T21: 0.272727 | U21: 0.363636 | V21: 0 | W21: 0 | X21: 0 | Y21: 0 | Z21: 0 | AA21: 0 | AB21: 0.363636 | AC21: =SUM(J21:AB21) -> 0.999999 | AD21: Оценка, 2 очереди
B22: GTL-установка у ст. Бованенково + налив | C22: — | D22: нет | E22: 0 | F22: 0 | G22: 0 | H22: 0 | I22: 1 | J22: 0 | K22: 0 | L22: 0 | M22: 0 | N22: 0.4 | O22: 0.6 | P22: 0 | Q22: 0 | R22: 0 | S22: 0 | T22: 0 | U22: 0 | V22: 0 | W22: 0 | X22: 0 | Y22: 0 | Z22: 0 | AA22: 0 | AB22: 0 | AC22: =SUM(J22:AB22) -> 1 | AD22: 76,5 тыс. т/год синт. УВ × $1500 за т/год × 85 руб/$ ≈ 9,75 + налив и резервуары ≈ 1,0 (INFRA)
B24: Суммы для ВЖК, автодороги и GTL задаются на листе «Сценарии» (меняются по вариантам).

Sheet Сценарии
B2: Параметры вариантов и сценариев
B3: Каждый столбец управляет своим листом «Расчёт_…». Жёлтым выделены ключевые решения команды.
B5: Параметр | C5: Ед. | D5: А. НТС + стабилизация | E5: Б. ТДА + ГФУ (СУГ) | F5: В. Б + этан | G5: Г. НТС на ТДА, без GTL | H5: Наш выбор: ТДА + GTL 40+30 | I5: Наш выбор — дебит 0,55 | J5: Наш выбор — цены ДТ/керосина 40 000/47 500 | K5: Наш выбор — без коэффициента Кр
B6: Технология подготовки (столбец баланса) | C6: код | D6: A | E6: B | F6: C | G6: T | H6: T | I6: T | J6: T | K6: T
B7: Состав объектов CAPEX (флаг на листе «CAPEX_нормы») | C7: код | D7: A | E7: B | F7: C | G7: T0 | H7: T | I7: T | J7: T | K7: T
B8: GTL-установка (1 — есть) | C8: 0/1 | D8: 0 | E8: 0 | F8: 0 | G8: 0 | H8: 1 | I8: 1 | J8: 1 | K8: 1
B9: Полка добычи | C9: млрд м³/год | D9: 12 | E9: 12 | F9: 12 | G9: 12 | H9: 12 | I9: 12 | J9: 12 | K9: 12
B10: Темп падения после полки (подобран: Σ добычи = извлекаемые) | C10: 1/год | D10: 0.071752 | E10: 0.071752 | F10: 0.071752 | G10: 0.071752 | H10: 0.071752 | I10: 0.071752 | J10: 0.071752 | K10: 0.071752
B11: Стоимость скважины | C11: млрд руб | D11: 1.5 | E11: 1.5 | F11: 1.5 | G11: 1.5 | H11: 1.5 | I11: 1.5 | J11: 1.5 | K11: 1.5
B12: Дебит скважины | C12: млн м³/сут | D12: 0.75 | E12: 0.75 | F12: 0.75 | G12: 0.75 | H12: 0.75 | I12: 0.55 | J12: 0.75 | K12: 0.75
B13: Применять Кр (п-ов Ямал) в НДПИ (1 — да) | C13: 0/1 | D13: 1 | E13: 1 | F13: 1 | G13: 1 | H13: 1 | I13: 1 | J13: 1 | K13: 0
B14: Цена ДТ GTL | C14: руб/т | D14: =Исходные!$C$47 -> 56100 | E14: =Исходные!$C$47 -> 56100 | F14: =Исходные!$C$47 -> 56100 | G14: =Исходные!$C$47 -> 56100 | H14: =Исходные!$C$47 -> 56100 | I14: =Исходные!$C$47 -> 56100 | J14: 40000 | K14: =Исходные!$C$47 -> 56100
B15: Цена авиакеросина GTL | C15: руб/т | D15: =Исходные!$C$48 -> 64500 | E15: =Исходные!$C$48 -> 64500 | F15: =Исходные!$C$48 -> 64500 | G15: =Исходные!$C$48 -> 64500 | H15: =Исходные!$C$48 -> 64500 | I15: =Исходные!$C$48 -> 64500 | J15: 47500 | K15: =Исходные!$C$48 -> 64500
B16: Оптовая цена газа (7900 ккал/м³) | C16: руб/1000 м³ | D16: =Исходные!$C$13 -> 4705 | E16: =Исходные!$C$13 -> 4705 | F16: =Исходные!$C$13 -> 4705 | G16: =Исходные!$C$13 -> 4705 | H16: =Исходные!$C$13 -> 4705 | I16: =Исходные!$C$13 -> 4705 | J16: =Исходные!$C$13 -> 4705 | K16: =Исходные!$C$13 -> 4705
B17: Brent | C17: $/барр. | D17: =Исходные!$C$14 -> 65 | E17: =Исходные!$C$14 -> 65 | F17: =Исходные!$C$14 -> 65 | G17: =Исходные!$C$14 -> 65 | H17: =Исходные!$C$14 -> 65 | I17: =Исходные!$C$14 -> 65 | J17: =Исходные!$C$14 -> 65 | K17: =Исходные!$C$14 -> 65
B18: Ставка дисконтирования (реальная) | C18: доля | D18: 0.1 | E18: 0.1 | F18: 0.1 | G18: 0.1 | H18: 0.1 | I18: 0.1 | J18: 0.1 | K18: 0.1
B19: Множитель CAPEX | C19: x | D19: 1 | E19: 1 | F19: 1 | G19: 1 | H19: 1 | I19: 1 | J19: 1 | K19: 1
B20: Множитель добычи | C20: x | D20: 1 | E20: 1 | F20: 1 | G20: 1 | H20: 1 | I20: 1 | J20: 1 | K20: 1
B21: ВЖК у УКПГ | C21: млрд руб | D21: 4 | E21: 4 | F21: 4 | G21: 4 | H21: 4 | I21: 4 | J21: 4 | K21: 4
B22: Автодорога 120 км | C22: млрд руб | D22: 24 | E22: 24 | F22: 24 | G22: 24 | H22: 24 | I22: 24 | J22: 24 | K22: 24
B23: GTL-установка + налив | C23: млрд руб | D23: 10.75 | E23: 10.75 | F23: 10.75 | G23: 10.75 | H23: 10.75 | I23: 10.75 | J23: 10.75 | K23: 10.75
B24: Услуги чужого ВЖК (проживание, транспорт) | C24: млрд руб/год | D24: 0 | E24: 0 | F24: 0 | G24: 0 | H24: 0 | I24: 0 | J24: 0 | K24: 0
B26: Описание | D26: Базовая технология без ТДА и без GTL | E26: Глубокое извлечение C3+, СУГ по ж/д | F26: Криогенное извлечение этана, потребителя нет | G26: Наша технология подготовки без GTL | H26: Базовый вариант решения команды | I26: Стресс: дебит как у наклонных скважин | J26: Цены продукции GTL по оценке команды | K26: Без льготы НДПИ для п-ова Ямал
B28: Темп падения подбирается так, чтобы суммарная добыча за 2031–2066 гг. равнялась извлекаемым запасам (проверка — на каждом листе «Расчёт», ячейка C11). При изменении полки подберите темп через «Подбор параметра».

Sheet Расчёт_А
B2: Расчёт: А. НТС + стабилизация
B3: Базовая технология без ТДА и без GTL. Денежный поток по годам, млрд руб. (реальные цены 2026 г.)
B5: ЧДД (NPV) при ставке варианта, млрд руб | C5: =SUM(E107:AR107) -> 15.105132
B6: ВНД (IRR), реальная | C6: =IRR(E105:AR105,0.1) -> 0.10741094
B7: Дисконтированная окупаемость, год | C7: =IF(SUM(E109:AR109)=0,"нет",2067-SUM(E109:AR109)) -> 2050
B8: Индекс доходности (PI) | C8: =1+C5/SUMPRODUCT(E93:AR93,E106:AR106) -> 1.0613708
B9: CAPEX всего, млрд руб | C9: =D93 -> 347.05583
B10: Фонд скважин, шт. | C10: =$D$42 -> 57.142857
B11: Проверка: Σ профиля − извлекаемые (должно быть ≈ 0), млрд м³ | C11: =D50-Исходные!$C$8 -> 0.0003531191
B13: Показатель | C13: Ед. | D13: Итого / знач. | E13: 2027 | F13: 2028 | G13: 2029 | H13: 2030 | I13: 2031 | J13: 2032 | K13: 2033 | L13: 2034 | M13: 2035 | N13: 2036 | O13: 2037 | P13: 2038 | Q13: 2039 | R13: 2040 | S13: 2041 | T13: 2042 | U13: 2043 | V13: 2044 | W13: 2045 | X13: 2046 | Y13: 2047 | Z13: 2048 | AA13: 2049 | AB13: 2050 | AC13: 2051 | AD13: 2052 | AE13: 2053 | AF13: 2054 | AG13: 2055 | AH13: 2056 | AI13: 2057 | AJ13: 2058 | AK13: 2059 | AL13: 2060 | AM13: 2061 | AN13: 2062 | AO13: 2063 | AP13: 2064 | AQ13: 2065 | AR13: 2066
B14: Параметры варианта (ссылки на «Сценарии» и «Исходные»)
B15: Технология (столбец баланса) | C15: код | D15: =Сценарии!$D$6 -> A
B16: Состав CAPEX | C16: код | D16: =Сценарии!$D$7 -> A
B17: GTL (1 — есть) | C17: 0/1 | D17: =Сценарии!$D$8 -> 0
B18: Полка добычи | C18: млрд м³/год | D18: =Сценарии!$D$9 -> 12
B19: Темп падения | C19: 1/год | D19: =Сценарии!$D$10 -> 0.071752
B20: Стоимость скважины | C20: млрд руб | D20: =Сценарии!$D$11 -> 1.5
B21: Дебит скважины | C21: млн м³/сут | D21: =Сценарии!$D$12 -> 0.75
B22: Кр (п-ов Ямал) в НДПИ | C22: 0/1 | D22: =Сценарии!$D$13 -> 1
B23: Цена ДТ GTL | C23: руб/т | D23: =Сценарии!$D$14 -> 56100
B24: Цена керосина GTL | C24: руб/т | D24: =Сценарии!$D$15 -> 64500
B25: Цена газа | C25: руб/1000 м³ | D25: =Сценарии!$D$16 -> 4705
B26: Brent | C26: $/барр. | D26: =Сценарии!$D$17 -> 65
B27: Ставка дисконтирования | C27: доля | D27: =Сценарии!$D$18 -> 0.1
B28: Множитель CAPEX | C28: x | D28: =Сценарии!$D$19 -> 1
B29: Множитель добычи | C29: x | D29: =Сценарии!$D$20 -> 1
B30: ВЖК у УКПГ | C30: млрд руб | D30: =Сценарии!$D$21 -> 4
B31: Автодорога | C31: млрд руб | D31: =Сценарии!$D$22 -> 24
B32: GTL + налив | C32: млрд руб | D32: =Сценарии!$D$23 -> 10.75
B33: Услуги чужого ВЖК | C33: млрд руб/год | D33: =Сценарии!$D$24 -> 0
B34: Выход конденсата | C34: кг/1000 м³ | D34: =INDEX(Баланс!$D$18:$G$18,MATCH($D$15,Баланс!$D$17:$G$17,0)) -> 37.3202
B35: Выход СУГ | C35: кг/1000 м³ | D35: =INDEX(Баланс!$D$19:$G$19,MATCH($D$15,Баланс!$D$17:$G$17,0)) -> 0
B36: Выход этана | C36: кг/1000 м³ | D36: =INDEX(Баланс!$D$20:$G$20,MATCH($D$15,Баланс!$D$17:$G$17,0)) -> 0
B37: Товарный газ | C37: м³/1000 м³ | D37: =INDEX(Баланс!$D$21:$G$21,MATCH($D$15,Баланс!$D$17:$G$17,0)) -> 989.85993
B38: Теплота сгорания товарного газа | C38: МДж/м³ | D38: =INDEX(Баланс!$D$22:$G$22,MATCH($D$15,Баланс!$D$17:$G$17,0)) -> 36.697221
B39: Цена товарного газа с учётом теплоты | C39: руб/1000 м³ | D39: =$D$25*$D$38/Исходные!$C$12 -> 5220.1562
B40: Нетбэк конденсата на промысле | C40: руб/т | D40: =($D$26-Исходные!$C$16)*Исходные!$C$17*Исходные!$C$15-Исходные!$C$18 -> 37376
B41: Коэффициент масштаба объектов (полка/14)^0,7 | C41: x | D41: =($D$18/14)^0.7 -> 0.89771245
B42: Фонд эксплуатационных скважин | C42: шт. | D42: =100*$D$18/14*0.5/$D$21 -> 57.142857
B43: GTL: синтетические УВ | C43: млн т/год | D43: =(Исходные!$C$39+Исходные!$C$40)/Исходные!$C$38/1000 -> 0.076502732
...

Sheet Расчёт_Б
B2: Расчёт: Б. ТДА + ГФУ (СУГ)
B3: Глубокое извлечение C3+, СУГ по ж/д. Денежный поток по годам, млрд руб. (реальные цены 2026 г.)
B5: ЧДД (NPV) при ставке варианта, млрд руб | C5: =SUM(E107:AR107) -> -9.3797347
B6: ВНД (IRR), реальная | C6: =IRR(E105:AR105,0.1) -> 0.096053345
B7: Дисконтированная окупаемость, год | C7: =IF(SUM(E109:AR109)=0,"нет",2067-SUM(E109:AR109)) -> нет
B8: Индекс доходности (PI) | C8: =1+C5/SUMPRODUCT(E93:AR93,E106:AR106) -> 0.96857102
B9: CAPEX всего, млрд руб | C9: =D93 -> 423.0023
B10: Фонд скважин, шт. | C10: =$D$42 -> 57.142857
B11: Проверка: Σ профиля − извлекаемые (должно быть ≈ 0), млрд м³ | C11: =D50-Исходные!$C$8 -> 0.0003531191
B13: Показатель | C13: Ед. | D13: Итого / знач. | E13: 2027 | F13: 2028 | G13: 2029 | H13: 2030 | I13: 2031 | J13: 2032 | K13: 2033 | L13: 2034 | M13: 2035 | N13: 2036 | O13: 2037 | P13: 2038 | Q13: 2039 | R13: 2040 | S13: 2041 | T13: 2042 | U13: 2043 | V13: 2044 | W13: 2045 | X13: 2046 | Y13: 2047 | Z13: 2048 | AA13: 2049 | AB13: 2050 | AC13: 2051 | AD13: 2052 | AE13: 2053 | AF13: 2054 | AG13: 2055 | AH13: 2056 | AI13: 2057 | AJ13: 2058 | AK13: 2059 | AL13: 2060 | AM13: 2061 | AN13: 2062 | AO13: 2063 | AP13: 2064 | AQ13: 2065 | AR13: 2066
B14: Параметры варианта (ссылки на «Сценарии» и «Исходные»)
B15: Технология (столбец баланса) | C15: код | D15: =Сценарии!$E$6 -> B
B16: Состав CAPEX | C16: код | D16: =Сценарии!$E$7 -> B
B17: GTL (1 — есть) | C17: 0/1 | D17: =Сценарии!$E$8 -> 0
B18: Полка добычи | C18: млрд м³/год | D18: =Сценарии!$E$9 -> 12
B19: Темп падения | C19: 1/год | D19: =Сценарии!$E$10 -> 0.071752
B20: Стоимость скважины | C20: млрд руб | D20: =Сценарии!$E$11 -> 1.5
B21: Дебит скважины | C21: млн м³/сут | D21: =Сценарии!$E$12 -> 0.75
B22: Кр (п-ов Ямал) в НДПИ | C22: 0/1 | D22: =Сценарии!$E$13 -> 1
B23: Цена ДТ GTL | C23: руб/т | D23: =Сценарии!$E$14 -> 56100
B24: Цена керосина GTL | C24: руб/т | D24: =Сценарии!$E$15 -> 64500
B25: Цена газа | C25: руб/1000 м³ | D25: =Сценарии!$E$16 -> 4705
B26: Brent | C26: $/барр. | D26: =Сценарии!$E$17 -> 65
B27: Ставка дисконтирования | C27: доля | D27: =Сценарии!$E$18 -> 0.1
B28: Множитель CAPEX | C28: x | D28: =Сценарии!$E$19 -> 1
B29: Множитель добычи | C29: x | D29: =Сценарии!$E$20 -> 1
B30: ВЖК у УКПГ | C30: млрд руб | D30: =Сценарии!$E$21 -> 4
B31: Автодорога | C31: млрд руб | D31: =Сценарии!$E$22 -> 24
B32: GTL + налив | C32: млрд руб | D32: =Сценарии!$E$23 -> 10.75
B33: Услуги чужого ВЖК | C33: млрд руб/год | D33: =Сценарии!$E$24 -> 0
B34: Выход конденсата | C34: кг/1000 м³ | D34: =INDEX(Баланс!$D$18:$G$18,MATCH($D$15,Баланс!$D$17:$G$17,0)) -> 32.941018
B35: Выход СУГ | C35: кг/1000 м³ | D35: =INDEX(Баланс!$D$19:$G$19,MATCH($D$15,Баланс!$D$17:$G$17,0)) -> 72.968324
B36: Выход этана | C36: кг/1000 м³ | D36: =INDEX(Баланс!$D$20:$G$20,MATCH($D$15,Баланс!$D$17:$G$17,0)) -> 0
B37: Товарный газ | C37: м³/1000 м³ | D37: =INDEX(Баланс!$D$21:$G$21,MATCH($D$15,Баланс!$D$17:$G$17,0)) -> 955.35768
B38: Теплота сгорания товарного газа | C38: МДж/м³ | D38: =INDEX(Баланс!$D$22:$G$22,MATCH($D$15,Баланс!$D$17:$G$17,0)) -> 34.707378
B39: Цена товарного газа с учётом теплоты | C39: руб/1000 м³ | D39: =$D$25*$D$38/Исходные!$C$12 -> 4937.1023
B40: Нетбэк конденсата на промысле | C40: руб/т | D40: =($D$26-Исходные!$C$16)*Исходные!$C$17*Исходные!$C$15-Исходные!$C$18 -> 37376
B41: Коэффициент масштаба объектов (полка/14)^0,7 | C41: x | D41: =($D$18/14)^0.7 -> 0.89771245
B42: Фонд эксплуатационных скважин | C42: шт. | D42: =100*$D$18/14*0.5/$D$21 -> 57.142857
B43: GTL: синтетические УВ | C43: млн т/год | D43: =(Исходные!$C$39+Исходные!$C$40)/Исходные!$C$38/1000 -> 0.076502732
...

Sheet Расчёт_В
B2: Расчёт: В. Б + этан
B3: Криогенное извлечение этана, потребителя нет. Денежный поток по годам, млрд руб. (реальные цены 2026 г.)
B5: ЧДД (NPV) при ставке варианта, млрд руб | C5: =SUM(E107:AR107) -> -75.259733
B6: ВНД (IRR), реальная | C6: =IRR(E105:AR105,0.1) -> 0.071124893
B7: Дисконтированная окупаемость, год | C7: =IF(SUM(E109:AR109)=0,"нет",2067-SUM(E109:AR109)) -> нет
B8: Индекс доходности (PI) | C8: =1+C5/SUMPRODUCT(E93:AR93,E106:AR106) -> 0.78210017
B9: CAPEX всего, млрд руб | C9: =D93 -> 485.84218
B10: Фонд скважин, шт. | C10: =$D$42 -> 57.142857
B11: Проверка: Σ профиля − извлекаемые (должно быть ≈ 0), млрд м³ | C11: =D50-Исходные!$C$8 -> 0.0003531191
B13: Показатель | C13: Ед. | D13: Итого / знач. | E13: 2027 | F13: 2028 | G13: 2029 | H13: 2030 | I13: 2031 | J13: 2032 | K13: 2033 | L13: 2034 | M13: 2035 | N13: 2036 | O13: 2037 | P13: 2038 | Q13: 2039 | R13: 2040 | S13: 2041 | T13: 2042 | U13: 2043 | V13: 2044 | W13: 2045 | X13: 2046 | Y13: 2047 | Z13: 2048 | AA13: 2049 | AB13: 2050 | AC13: 2051 | AD13: 2052 | AE13: 2053 | AF13: 2054 | AG13: 2055 | AH13: 2056 | AI13: 2057 | AJ13: 2058 | AK13: 2059 | AL13: 2060 | AM13: 2061 | AN13: 2062 | AO13: 2063 | AP13: 2064 | AQ13: 2065 | AR13: 2066
B14: Параметры варианта (ссылки на «Сценарии» и «Исходные»)
B15: Технология (столбец баланса) | C15: код | D15: =Сценарии!$F$6 -> C
B16: Состав CAPEX | C16: код | D16: =Сценарии!$F$7 -> C
B17: GTL (1 — есть) | C17: 0/1 | D17: =Сценарии!$F$8 -> 0
B18: Полка добычи | C18: млрд м³/год | D18: =Сценарии!$F$9 -> 12
B19: Темп падения | C19: 1/год | D19: =Сценарии!$F$10 -> 0.071752
B20: Стоимость скважины | C20: млрд руб | D20: =Сценарии!$F$11 -> 1.5
B21: Дебит скважины | C21: млн м³/сут | D21: =Сценарии!$F$12 -> 0.75
B22: Кр (п-ов Ямал) в НДПИ | C22: 0/1 | D22: =Сценарии!$F$13 -> 1
B23: Цена ДТ GTL | C23: руб/т | D23: =Сценарии!$F$14 -> 56100
B24: Цена керосина GTL | C24: руб/т | D24: =Сценарии!$F$15 -> 64500
B25: Цена газа | C25: руб/1000 м³ | D25: =Сценарии!$F$16 -> 4705
B26: Brent | C26: $/барр. | D26: =Сценарии!$F$17 -> 65
B27: Ставка дисконтирования | C27: доля | D27: =Сценарии!$F$18 -> 0.1
B28: Множитель CAPEX | C28: x | D28: =Сценарии!$F$19 -> 1
B29: Множитель добычи | C29: x | D29: =Сценарии!$F$20 -> 1
B30: ВЖК у УКПГ | C30: млрд руб | D30: =Сценарии!$F$21 -> 4
B31: Автодорога | C31: млрд руб | D31: =Сценарии!$F$22 -> 24
B32: GTL + налив | C32: млрд руб | D32: =Сценарии!$F$23 -> 10.75
B33: Услуги чужого ВЖК | C33: млрд руб/год | D33: =Сценарии!$F$24 -> 0
B34: Выход конденсата | C34: кг/1000 м³ | D34: =INDEX(Баланс!$D$18:$G$18,MATCH($D$15,Баланс!$D$17:$G$17,0)) -> 33.107387
B35: Выход СУГ | C35: кг/1000 м³ | D35: =INDEX(Баланс!$D$19:$G$19,MATCH($D$15,Баланс!$D$17:$G$17,0)) -> 77.853527
B36: Выход этана | C36: кг/1000 м³ | D36: =INDEX(Баланс!$D$20:$G$20,MATCH($D$15,Баланс!$D$17:$G$17,0)) -> 58.467219
B37: Товарный газ | C37: м³/1000 м³ | D37: =INDEX(Баланс!$D$21:$G$21,MATCH($D$15,Баланс!$D$17:$G$17,0)) -> 905.94297
B38: Теплота сгорания товарного газа | C38: МДж/м³ | D38: =INDEX(Баланс!$D$22:$G$22,MATCH($D$15,Баланс!$D$17:$G$17,0)) -> 33.272649
B39: Цена товарного газа с учётом теплоты | C39: руб/1000 м³ | D39: =$D$25*$D$38/Исходные!$C$12 -> 4733.0131
B40: Нетбэк конденсата на промысле | C40: руб/т | D40: =($D$26-Исходные!$C$16)*Исходные!$C$17*Исходные!$C$15-Исходные!$C$18 -> 37376
B41: Коэффициент масштаба объектов (полка/14)^0,7 | C41: x | D41: =($D$18/14)^0.7 -> 0.89771245
B42: Фонд эксплуатационных скважин | C42: шт. | D42: =100*$D$18/14*0.5/$D$21 -> 57.142857
B43: GTL: синтетические УВ | C43: млн т/год | D43: =(Исходные!$C$39+Исходные!$C$40)/Исходные!$C$38/1000 -> 0.076502732
...

Sheet Расчёт_Г
B2: Расчёт: Г. НТС на ТДА, без GTL
B3: Наша технология подготовки без GTL. Денежный поток по годам, млрд руб. (реальные цены 2026 г.)
B5: ЧДД (NPV) при ставке варианта, млрд руб | C5: =SUM(E107:AR107) -> 16.893083
B6: ВНД (IRR), реальная | C6: =IRR(E105:AR105,0.1) -> 0.10816471
B7: Дисконтированная окупаемость, год | C7: =IF(SUM(E109:AR109)=0,"нет",2067-SUM(E109:AR109)) -> 2049
B8: Индекс доходности (PI) | C8: =1+C5/SUMPRODUCT(E93:AR93,E106:AR106) -> 1.0677063
B9: CAPEX всего, млрд руб | C9: =D93 -> 351.54439
B10: Фонд скважин, шт. | C10: =$D$42 -> 57.142857
B11: Проверка: Σ профиля − извлекаемые (должно быть ≈ 0), млрд м³ | C11: =D50-Исходные!$C$8 -> 0.0003531191
B13: Показатель | C13: Ед. | D13: Итого / знач. | E13: 2027 | F13: 2028 | G13: 2029 | H13: 2030 | I13: 2031 | J13: 2032 | K13: 2033 | L13: 2034 | M13: 2035 | N13: 2036 | O13: 2037 | P13: 2038 | Q13: 2039 | R13: 2040 | S13: 2041 | T13: 2042 | U13: 2043 | V13: 2044 | W13: 2045 | X13: 2046 | Y13: 2047 | Z13: 2048 | AA13: 2049 | AB13: 2050 | AC13: 2051 | AD13: 2052 | AE13: 2053 | AF13: 2054 | AG13: 2055 | AH13: 2056 | AI13: 2057 | AJ13: 2058 | AK13: 2059 | AL13: 2060 | AM13: 2061 | AN13: 2062 | AO13: 2063 | AP13: 2064 | AQ13: 2065 | AR13: 2066
B14: Параметры варианта (ссылки на «Сценарии» и «Исходные»)
B15: Технология (столбец баланса) | C15: код | D15: =Сценарии!$G$6 -> T
B16: Состав CAPEX | C16: код | D16: =Сценарии!$G$7 -> T0
B17: GTL (1 — есть) | C17: 0/1 | D17: =Сценарии!$G$8 -> 0
B18: Полка добычи | C18: млрд м³/год | D18: =Сценарии!$G$9 -> 12
B19: Темп падения | C19: 1/год | D19: =Сценарии!$G$10 -> 0.071752
B20: Стоимость скважины | C20: млрд руб | D20: =Сценарии!$G$11 -> 1.5
B21: Дебит скважины | C21: млн м³/сут | D21: =Сценарии!$G$12 -> 0.75
B22: Кр (п-ов Ямал) в НДПИ | C22: 0/1 | D22: =Сценарии!$G$13 -> 1
B23: Цена ДТ GTL | C23: руб/т | D23: =Сценарии!$G$14 -> 56100
B24: Цена керосина GTL | C24: руб/т | D24: =Сценарии!$G$15 -> 64500
B25: Цена газа | C25: руб/1000 м³ | D25: =Сценарии!$G$16 -> 4705
B26: Brent | C26: $/барр. | D26: =Сценарии!$G$17 -> 65
B27: Ставка дисконтирования | C27: доля | D27: =Сценарии!$G$18 -> 0.1
B28: Множитель CAPEX | C28: x | D28: =Сценарии!$G$19 -> 1
B29: Множитель добычи | C29: x | D29: =Сценарии!$G$20 -> 1
B30: ВЖК у УКПГ | C30: млрд руб | D30: =Сценарии!$G$21 -> 4
B31: Автодорога | C31: млрд руб | D31: =Сценарии!$G$22 -> 24
B32: GTL + налив | C32: млрд руб | D32: =Сценарии!$G$23 -> 10.75
B33: Услуги чужого ВЖК | C33: млрд руб/год | D33: =Сценарии!$G$24 -> 0
B34: Выход конденсата | C34: кг/1000 м³ | D34: =INDEX(Баланс!$D$18:$G$18,MATCH($D$15,Баланс!$D$17:$G$17,0)) -> 41.334488
B35: Выход СУГ | C35: кг/1000 м³ | D35: =INDEX(Баланс!$D$19:$G$19,MATCH($D$15,Баланс!$D$17:$G$17,0)) -> 0
B36: Выход этана | C36: кг/1000 м³ | D36: =INDEX(Баланс!$D$20:$G$20,MATCH($D$15,Баланс!$D$17:$G$17,0)) -> 0
B37: Товарный газ | C37: м³/1000 м³ | D37: =INDEX(Баланс!$D$21:$G$21,MATCH($D$15,Баланс!$D$17:$G$17,0)) -> 988.42921
B38: Теплота сгорания товарного газа | C38: МДж/м³ | D38: =INDEX(Баланс!$D$22:$G$22,MATCH($D$15,Баланс!$D$17:$G$17,0)) -> 36.565304
B39: Цена товарного газа с учётом теплоты | C39: руб/1000 м³ | D39: =$D$25*$D$38/Исходные!$C$12 -> 5201.3911
B40: Нетбэк конденсата на промысле | C40: руб/т | D40: =($D$26-Исходные!$C$16)*Исходные!$C$17*Исходные!$C$15-Исходные!$C$18 -> 37376
B41: Коэффициент масштаба объектов (полка/14)^0,7 | C41: x | D41: =($D$18/14)^0.7 -> 0.89771245
B42: Фонд эксплуатационных скважин | C42: шт. | D42: =100*$D$18/14*0.5/$D$21 -> 57.142857
B43: GTL: синтетические УВ | C43: млн т/год | D43: =(Исходные!$C$39+Исходные!$C$40)/Исходные!$C$38/1000 -> 0.076502732
...

Sheet Расчёт_Наш
B2: Расчёт: Наш выбор: ТДА + GTL 40+30
B3: Базовый вариант решения команды. Денежный поток по годам, млрд руб. (реальные цены 2026 г.)
B5: ЧДД (NPV) при ставке варианта, млрд руб | C5: =SUM(E107:AR107) -> 22.511796
B6: ВНД (IRR), реальная | C6: =IRR(E105:AR105,0.1) -> 0.11044479
B7: Дисконтированная окупаемость, год | C7: =IF(SUM(E109:AR109)=0,"нет",2067-SUM(E109:AR109)) -> 2048
B8: Индекс доходности (PI) | C8: =1+C5/SUMPRODUCT(E93:AR93,E106:AR106) -> 1.0878941
B9: CAPEX всего, млрд руб | C9: =D93 -> 362.29439
B10: Фонд скважин, шт. | C10: =$D$42 -> 57.142857
B11: Проверка: Σ профиля − извлекаемые (должно быть ≈ 0), млрд м³ | C11: =D50-Исходные!$C$8 -> 0.0003531191
B13: Показатель | C13: Ед. | D13: Итого / знач. | E13: 2027 | F13: 2028 | G13: 2029 | H13: 2030 | I13: 2031 | J13: 2032 | K13: 2033 | L13: 2034 | M13: 2035 | N13: 2036 | O13: 2037 | P13: 2038 | Q13: 2039 | R13: 2040 | S13: 2041 | T13: 2042 | U13: 2043 | V13: 2044 | W13: 2045 | X13: 2046 | Y13: 2047 | Z13: 2048 | AA13: 2049 | AB13: 2050 | AC13: 2051 | AD13: 2052 | AE13: 2053 | AF13: 2054 | AG13: 2055 | AH13: 2056 | AI13: 2057 | AJ13: 2058 | AK13: 2059 | AL13: 2060 | AM13: 2061 | AN13: 2062 | AO13: 2063 | AP13: 2064 | AQ13: 2065 | AR13: 2066
B14: Параметры варианта (ссылки на «Сценарии» и «Исходные»)
B15: Технология (столбец баланса) | C15: код | D15: =Сценарии!$H$6 -> T
B16: Состав CAPEX | C16: код | D16: =Сценарии!$H$7 -> T
B17: GTL (1 — есть) | C17: 0/1 | D17: =Сценарии!$H$8 -> 1
B18: Полка добычи | C18: млрд м³/год | D18: =Сценарии!$H$9 -> 12
B19: Темп падения | C19: 1/год | D19: =Сценарии!$H$10 -> 0.071752
B20: Стоимость скважины | C20: млрд руб | D20: =Сценарии!$H$11 -> 1.5
B21: Дебит скважины | C21: млн м³/сут | D21: =Сценарии!$H$12 -> 0.75
B22: Кр (п-ов Ямал) в НДПИ | C22: 0/1 | D22: =Сценарии!$H$13 -> 1
B23: Цена ДТ GTL | C23: руб/т | D23: =Сценарии!$H$14 -> 56100
B24: Цена керосина GTL | C24: руб/т | D24: =Сценарии!$H$15 -> 64500
B25: Цена газа | C25: руб/1000 м³ | D25: =Сценарии!$H$16 -> 4705
B26: Brent | C26: $/барр. | D26: =Сценарии!$H$17 -> 65
B27: Ставка дисконтирования | C27: доля | D27: =Сценарии!$H$18 -> 0.1
B28: Множитель CAPEX | C28: x | D28: =Сценарии!$H$19 -> 1
B29: Множитель добычи | C29: x | D29: =Сценарии!$H$20 -> 1
B30: ВЖК у УКПГ | C30: млрд руб | D30: =Сценарии!$H$21 -> 4
B31: Автодорога | C31: млрд руб | D31: =Сценарии!$H$22 -> 24
B32: GTL + налив | C32: млрд руб | D32: =Сценарии!$H$23 -> 10.75
B33: Услуги чужого ВЖК | C33: млрд руб/год | D33: =Сценарии!$H$24 -> 0
B34: Выход конденсата | C34: кг/1000 м³ | D34: =INDEX(Баланс!$D$18:$G$18,MATCH($D$15,Баланс!$D$17:$G$17,0)) -> 41.334488
B35: Выход СУГ | C35: кг/1000 м³ | D35: =INDEX(Баланс!$D$19:$G$19,MATCH($D$15,Баланс!$D$17:$G$17,0)) -> 0
B36: Выход этана | C36: кг/1000 м³ | D36: =INDEX(Баланс!$D$20:$G$20,MATCH($D$15,Баланс!$D$17:$G$17,0)) -> 0
B37: Товарный газ | C37: м³/1000 м³ | D37: =INDEX(Баланс!$D$21:$G$21,MATCH($D$15,Баланс!$D$17:$G$17,0)) -> 988.42921
B38: Теплота сгорания товарного газа | C38: МДж/м³ | D38: =INDEX(Баланс!$D$22:$G$22,MATCH($D$15,Баланс!$D$17:$G$17,0)) -> 36.565304
B39: Цена товарного газа с учётом теплоты | C39: руб/1000 м³ | D39: =$D$25*$D$38/Исходные!$C$12 -> 5201.3911
B40: Нетбэк конденсата на промысле | C40: руб/т | D40: =($D$26-Исходные!$C$16)*Исходные!$C$17*Исходные!$C$15-Исходные!$C$18 -> 37376
B41: Коэффициент масштаба объектов (полка/14)^0,7 | C41: x | D41: =($D$18/14)^0.7 -> 0.89771245
B42: Фонд эксплуатационных скважин | C42: шт. | D42: =100*$D$18/14*0.5/$D$21 -> 57.142857
B43: GTL: синтетические УВ | C43: млн т/год | D43: =(Исходные!$C$39+Исходные!$C$40)/Исходные!$C$38/1000 -> 0.076502732
...

Sheet Расчёт_Наш_дебит
B2: Расчёт: Наш выбор — дебит 0,55
B3: Стресс: дебит как у наклонных скважин. Денежный поток по годам, млрд руб. (реальные цены 2026 г.)
B5: ЧДД (NPV) при ставке варианта, млрд руб | C5: =SUM(E107:AR107) -> -1.5517793
B6: ВНД (IRR), реальная | C6: =IRR(E105:AR105,0.1) -> 0.099321669
B7: Дисконтированная окупаемость, год | C7: =IF(SUM(E109:AR109)=0,"нет",2067-SUM(E109:AR109)) -> нет
B8: Индекс доходности (PI) | C8: =1+C5/SUMPRODUCT(E93:AR93,E106:AR106) -> 0.99442881
B9: CAPEX всего, млрд руб | C9: =D93 -> 393.46322
B10: Фонд скважин, шт. | C10: =$D$42 -> 77.922078
B11: Проверка: Σ профиля − извлекаемые (должно быть ≈ 0), млрд м³ | C11: =D50-Исходные!$C$8 -> 0.0003531191
B13: Показатель | C13: Ед. | D13: Итого / знач. | E13: 2027 | F13: 2028 | G13: 2029 | H13: 2030 | I13: 2031 | J13: 2032 | K13: 2033 | L13: 2034 | M13: 2035 | N13: 2036 | O13: 2037 | P13: 2038 | Q13: 2039 | R13: 2040 | S13: 2041 | T13: 2042 | U13: 2043 | V13: 2044 | W13: 2045 | X13: 2046 | Y13: 2047 | Z13: 2048 | AA13: 2049 | AB13: 2050 | AC13: 2051 | AD13: 2052 | AE13: 2053 | AF13: 2054 | AG13: 2055 | AH13: 2056 | AI13: 2057 | AJ13: 2058 | AK13: 2059 | AL13: 2060 | AM13: 2061 | AN13: 2062 | AO13: 2063 | AP13: 2064 | AQ13: 2065 | AR13: 2066
B14: Параметры варианта (ссылки на «Сценарии» и «Исходные»)
B15: Технология (столбец баланса) | C15: код | D15: =Сценарии!$I$6 -> T
B16: Состав CAPEX | C16: код | D16: =Сценарии!$I$7 -> T
B17: GTL (1 — есть) | C17: 0/1 | D17: =Сценарии!$I$8 -> 1
B18: Полка добычи | C18: млрд м³/год | D18: =Сценарии!$I$9 -> 12
B19: Темп падения | C19: 1/год | D19: =Сценарии!$I$10 -> 0.071752
B20: Стоимость скважины | C20: млрд руб | D20: =Сценарии!$I$11 -> 1.5
B21: Дебит скважины | C21: млн м³/сут | D21: =Сценарии!$I$12 -> 0.55
B22: Кр (п-ов Ямал) в НДПИ | C22: 0/1 | D22: =Сценарии!$I$13 -> 1
B23: Цена ДТ GTL | C23: руб/т | D23: =Сценарии!$I$14 -> 56100
B24: Цена керосина GTL | C24: руб/т | D24: =Сценарии!$I$15 -> 64500
B25: Цена газа | C25: руб/1000 м³ | D25: =Сценарии!$I$16 -> 4705
B26: Brent | C26: $/барр. | D26: =Сценарии!$I$17 -> 65
B27: Ставка дисконтирования | C27: доля | D27: =Сценарии!$I$18 -> 0.1
B28: Множитель CAPEX | C28: x | D28: =Сценарии!$I$19 -> 1
B29: Множитель добычи | C29: x | D29: =Сценарии!$I$20 -> 1
B30: ВЖК у УКПГ | C30: млрд руб | D30: =Сценарии!$I$21 -> 4
B31: Автодорога | C31: млрд руб | D31: =Сценарии!$I$22 -> 24
B32: GTL + налив | C32: млрд руб | D32: =Сценарии!$I$23 -> 10.75
B33: Услуги чужого ВЖК | C33: млрд руб/год | D33: =Сценарии!$I$24 -> 0
B34: Выход конденсата | C34: кг/1000 м³ | D34: =INDEX(Баланс!$D$18:$G$18,MATCH($D$15,Баланс!$D$17:$G$17,0)) -> 41.334488
B35: Выход СУГ | C35: кг/1000 м³ | D35: =INDEX(Баланс!$D$19:$G$19,MATCH($D$15,Баланс!$D$17:$G$17,0)) -> 0
B36: Выход этана | C36: кг/1000 м³ | D36: =INDEX(Баланс!$D$20:$G$20,MATCH($D$15,Баланс!$D$17:$G$17,0)) -> 0
B37: Товарный газ | C37: м³/1000 м³ | D37: =INDEX(Баланс!$D$21:$G$21,MATCH($D$15,Баланс!$D$17:$G$17,0)) -> 988.42921
B38: Теплота сгорания товарного газа | C38: МДж/м³ | D38: =INDEX(Баланс!$D$22:$G$22,MATCH($D$15,Баланс!$D$17:$G$17,0)) -> 36.565304
B39: Цена товарного газа с учётом теплоты | C39: руб/1000 м³ | D39: =$D$25*$D$38/Исходные!$C$12 -> 5201.3911
B40: Нетбэк конденсата на промысле | C40: руб/т | D40: =($D$26-Исходные!$C$16)*Исходные!$C$17*Исходные!$C$15-Исходные!$C$18 -> 37376
B41: Коэффициент масштаба объектов (полка/14)^0,7 | C41: x | D41: =($D$18/14)^0.7 -> 0.89771245
B42: Фонд эксплуатационных скважин | C42: шт. | D42: =100*$D$18/14*0.5/$D$21 -> 77.922078
B43: GTL: синтетические УВ | C43: млн т/год | D43: =(Исходные!$C$39+Исходные!$C$40)/Исходные!$C$38/1000 -> 0.076502732
...

Sheet Расчёт_Наш_цены
B2: Расчёт: Наш выбор — цены ДТ/керосина 40 000/47 500
B3: Цены продукции GTL по оценке команды. Денежный поток по годам, млрд руб. (реальные цены 2026 г.)
B5: ЧДД (NPV) при ставке варианта, млрд руб | C5: =SUM(E107:AR107) -> 17.588383
B6: ВНД (IRR), реальная | C6: =IRR(E105:AR105,0.1) -> 0.10824739
B7: Дисконтированная окупаемость, год | C7: =IF(SUM(E109:AR109)=0,"нет",2067-SUM(E109:AR109)) -> 2049
B8: Индекс доходности (PI) | C8: =1+C5/SUMPRODUCT(E93:AR93,E106:AR106) -> 1.0686713
B9: CAPEX всего, млрд руб | C9: =D93 -> 362.29439
B10: Фонд скважин, шт. | C10: =$D$42 -> 57.142857
B11: Проверка: Σ профиля − извлекаемые (должно быть ≈ 0), млрд м³ | C11: =D50-Исходные!$C$8 -> 0.0003531191
B13: Показатель | C13: Ед. | D13: Итого / знач. | E13: 2027 | F13: 2028 | G13: 2029 | H13: 2030 | I13: 2031 | J13: 2032 | K13: 2033 | L13: 2034 | M13: 2035 | N13: 2036 | O13: 2037 | P13: 2038 | Q13: 2039 | R13: 2040 | S13: 2041 | T13: 2042 | U13: 2043 | V13: 2044 | W13: 2045 | X13: 2046 | Y13: 2047 | Z13: 2048 | AA13: 2049 | AB13: 2050 | AC13: 2051 | AD13: 2052 | AE13: 2053 | AF13: 2054 | AG13: 2055 | AH13: 2056 | AI13: 2057 | AJ13: 2058 | AK13: 2059 | AL13: 2060 | AM13: 2061 | AN13: 2062 | AO13: 2063 | AP13: 2064 | AQ13: 2065 | AR13: 2066
B14: Параметры варианта (ссылки на «Сценарии» и «Исходные»)
B15: Технология (столбец баланса) | C15: код | D15: =Сценарии!$J$6 -> T
B16: Состав CAPEX | C16: код | D16: =Сценарии!$J$7 -> T
B17: GTL (1 — есть) | C17: 0/1 | D17: =Сценарии!$J$8 -> 1
B18: Полка добычи | C18: млрд м³/год | D18: =Сценарии!$J$9 -> 12
B19: Темп падения | C19: 1/год | D19: =Сценарии!$J$10 -> 0.071752
B20: Стоимость скважины | C20: млрд руб | D20: =Сценарии!$J$11 -> 1.5
B21: Дебит скважины | C21: млн м³/сут | D21: =Сценарии!$J$12 -> 0.75
B22: Кр (п-ов Ямал) в НДПИ | C22: 0/1 | D22: =Сценарии!$J$13 -> 1
B23: Цена ДТ GTL | C23: руб/т | D23: =Сценарии!$J$14 -> 40000
B24: Цена керосина GTL | C24: руб/т | D24: =Сценарии!$J$15 -> 47500
B25: Цена газа | C25: руб/1000 м³ | D25: =Сценарии!$J$16 -> 4705
B26: Brent | C26: $/барр. | D26: =Сценарии!$J$17 -> 65
B27: Ставка дисконтирования | C27: доля | D27: =Сценарии!$J$18 -> 0.1
B28: Множитель CAPEX | C28: x | D28: =Сценарии!$J$19 -> 1
B29: Множитель добычи | C29: x | D29: =Сценарии!$J$20 -> 1
B30: ВЖК у УКПГ | C30: млрд руб | D30: =Сценарии!$J$21 -> 4
B31: Автодорога | C31: млрд руб | D31: =Сценарии!$J$22 -> 24
B32: GTL + налив | C32: млрд руб | D32: =Сценарии!$J$23 -> 10.75
B33: Услуги чужого ВЖК | C33: млрд руб/год | D33: =Сценарии!$J$24 -> 0
B34: Выход конденсата | C34: кг/1000 м³ | D34: =INDEX(Баланс!$D$18:$G$18,MATCH($D$15,Баланс!$D$17:$G$17,0)) -> 41.334488
B35: Выход СУГ | C35: кг/1000 м³ | D35: =INDEX(Баланс!$D$19:$G$19,MATCH($D$15,Баланс!$D$17:$G$17,0)) -> 0
B36: Выход этана | C36: кг/1000 м³ | D36: =INDEX(Баланс!$D$20:$G$20,MATCH($D$15,Баланс!$D$17:$G$17,0)) -> 0
B37: Товарный газ | C37: м³/1000 м³ | D37: =INDEX(Баланс!$D$21:$G$21,MATCH($D$15,Баланс!$D$17:$G$17,0)) -> 988.42921
B38: Теплота сгорания товарного газа | C38: МДж/м³ | D38: =INDEX(Баланс!$D$22:$G$22,MATCH($D$15,Баланс!$D$17:$G$17,0)) -> 36.565304
B39: Цена товарного газа с учётом теплоты | C39: руб/1000 м³ | D39: =$D$25*$D$38/Исходные!$C$12 -> 5201.3911
B40: Нетбэк конденсата на промысле | C40: руб/т | D40: =($D$26-Исходные!$C$16)*Исходные!$C$17*Исходные!$C$15-Исходные!$C$18 -> 37376
B41: Коэффициент масштаба объектов (полка/14)^0,7 | C41: x | D41: =($D$18/14)^0.7 -> 0.89771245
B42: Фонд эксплуатационных скважин | C42: шт. | D42: =100*$D$18/14*0.5/$D$21 -> 57.142857
B43: GTL: синтетические УВ | C43: млн т/год | D43: =(Исходные!$C$39+Исходные!$C$40)/Исходные!$C$38/1000 -> 0.076502732
...

Sheet Расчёт_Наш_безКр
B2: Расчёт: Наш выбор — без коэффициента Кр
B3: Без льготы НДПИ для п-ова Ямал. Денежный поток по годам, млрд руб. (реальные цены 2026 г.)
B5: ЧДД (NPV) при ставке варианта, млрд руб | C5: =SUM(E107:AR107) -> 13.729305
B6: ВНД (IRR), реальная | C6: =IRR(E105:AR105,0.1) -> 0.10632689
B7: Дисконтированная окупаемость, год | C7: =IF(SUM(E109:AR109)=0,"нет",2067-SUM(E109:AR109)) -> 2051
B8: Индекс доходности (PI) | C8: =1+C5/SUMPRODUCT(E93:AR93,E106:AR106) -> 1.0536041
B9: CAPEX всего, млрд руб | C9: =D93 -> 362.29439
B10: Фонд скважин, шт. | C10: =$D$42 -> 57.142857
B11: Проверка: Σ профиля − извлекаемые (должно быть ≈ 0), млрд м³ | C11: =D50-Исходные!$C$8 -> 0.0003531191
B13: Показатель | C13: Ед. | D13: Итого / знач. | E13: 2027 | F13: 2028 | G13: 2029 | H13: 2030 | I13: 2031 | J13: 2032 | K13: 2033 | L13: 2034 | M13: 2035 | N13: 2036 | O13: 2037 | P13: 2038 | Q13: 2039 | R13: 2040 | S13: 2041 | T13: 2042 | U13: 2043 | V13: 2044 | W13: 2045 | X13: 2046 | Y13: 2047 | Z13: 2048 | AA13: 2049 | AB13: 2050 | AC13: 2051 | AD13: 2052 | AE13: 2053 | AF13: 2054 | AG13: 2055 | AH13: 2056 | AI13: 2057 | AJ13: 2058 | AK13: 2059 | AL13: 2060 | AM13: 2061 | AN13: 2062 | AO13: 2063 | AP13: 2064 | AQ13: 2065 | AR13: 2066
B14: Параметры варианта (ссылки на «Сценарии» и «Исходные»)
B15: Технология (столбец баланса) | C15: код | D15: =Сценарии!$K$6 -> T
B16: Состав CAPEX | C16: код | D16: =Сценарии!$K$7 -> T
B17: GTL (1 — есть) | C17: 0/1 | D17: =Сценарии!$K$8 -> 1
B18: Полка добычи | C18: млрд м³/год | D18: =Сценарии!$K$9 -> 12
B19: Темп падения | C19: 1/год | D19: =Сценарии!$K$10 -> 0.071752
B20: Стоимость скважины | C20: млрд руб | D20: =Сценарии!$K$11 -> 1.5
B21: Дебит скважины | C21: млн м³/сут | D21: =Сценарии!$K$12 -> 0.75
B22: Кр (п-ов Ямал) в НДПИ | C22: 0/1 | D22: =Сценарии!$K$13 -> 0
B23: Цена ДТ GTL | C23: руб/т | D23: =Сценарии!$K$14 -> 56100
B24: Цена керосина GTL | C24: руб/т | D24: =Сценарии!$K$15 -> 64500
B25: Цена газа | C25: руб/1000 м³ | D25: =Сценарии!$K$16 -> 4705
B26: Brent | C26: $/барр. | D26: =Сценарии!$K$17 -> 65
B27: Ставка дисконтирования | C27: доля | D27: =Сценарии!$K$18 -> 0.1
B28: Множитель CAPEX | C28: x | D28: =Сценарии!$K$19 -> 1
B29: Множитель добычи | C29: x | D29: =Сценарии!$K$20 -> 1
B30: ВЖК у УКПГ | C30: млрд руб | D30: =Сценарии!$K$21 -> 4
B31: Автодорога | C31: млрд руб | D31: =Сценарии!$K$22 -> 24
B32: GTL + налив | C32: млрд руб | D32: =Сценарии!$K$23 -> 10.75
B33: Услуги чужого ВЖК | C33: млрд руб/год | D33: =Сценарии!$K$24 -> 0
B34: Выход конденсата | C34: кг/1000 м³ | D34: =INDEX(Баланс!$D$18:$G$18,MATCH($D$15,Баланс!$D$17:$G$17,0)) -> 41.334488
B35: Выход СУГ | C35: кг/1000 м³ | D35: =INDEX(Баланс!$D$19:$G$19,MATCH($D$15,Баланс!$D$17:$G$17,0)) -> 0
B36: Выход этана | C36: кг/1000 м³ | D36: =INDEX(Баланс!$D$20:$G$20,MATCH($D$15,Баланс!$D$17:$G$17,0)) -> 0
B37: Товарный газ | C37: м³/1000 м³ | D37: =INDEX(Баланс!$D$21:$G$21,MATCH($D$15,Баланс!$D$17:$G$17,0)) -> 988.42921
B38: Теплота сгорания товарного газа | C38: МДж/м³ | D38: =INDEX(Баланс!$D$22:$G$22,MATCH($D$15,Баланс!$D$17:$G$17,0)) -> 36.565304
B39: Цена товарного газа с учётом теплоты | C39: руб/1000 м³ | D39: =$D$25*$D$38/Исходные!$C$12 -> 5201.3911
B40: Нетбэк конденсата на промысле | C40: руб/т | D40: =($D$26-Исходные!$C$16)*Исходные!$C$17*Исходные!$C$15-Исходные!$C$18 -> 37376
B41: Коэффициент масштаба объектов (полка/14)^0,7 | C41: x | D41: =($D$18/14)^0.7 -> 0.89771245
B42: Фонд эксплуатационных скважин | C42: шт. | D42: =100*$D$18/14*0.5/$D$21 -> 57.142857
B43: GTL: синтетические УВ | C43: млн т/год | D43: =(Исходные!$C$39+Исходные!$C$40)/Исходные!$C$38/1000 -> 0.076502732
...

Sheet Чувствительность
B2: Как проект стал прибыльным, чувствительность и точки безубыточности
B3: Снимок результатов многовариантного пересчёта той же модели (Python-копия формул листа «Расчёт_Наш»). При изменении исходных данных пересчитайте.
B5: Шаг | C5: Эффект на NPV | D5: NPV после шага | E5: Комментарий
B6: Решение v3 (25.10.2026): GTL 90+60 тыс. т, скв. 1,95 млрд, без ВЖК, полка 8 | D6: -29.98 | E6: Исходная точка — расчёт предыдущей версии
B7: GTL 40 тыс. т ДТ + 30 тыс. т керосина (внутренние нужды) | C7: -0.64 | D7: -30.61 | E7: CAPEX GTL 23 → 10,75 млрд руб
B8: Стоимость скважины 1,5 млрд руб | C8: 18.05 | D8: -12.57 | E8: Решение команды
B9: Свой ВЖК у УКПГ вместо услуг ВЖК Бованенково | C9: -2.08 | D9: -14.65 | E9: CAPEX +4 млрд, минус 0,25 млрд/год услуг
B10: Горизонтальные скважины, дебит 0,75 млн м³/сут | C10: 16.04 | D10: 1.39 | E10: Харасавэй: испытания до 1,2 млн м³/сут; Юрхаровское: 1,6 вместо 0,8 млн м³/сут
B11: Полка 12 млрд м³/год (оптимум при новых затратах) | C11: 7.41 | D11: 8.81 | E11: См. таблицу полок ниже
B12: Коэффициент Кр в НДПИ (п-ов Ямал) | C12: 8.78 | D12: 17.59 | E12: НК РФ ст. 342.4 п. 9
B13: Трансфертная цена GTL = 80 % биржи без НДС | C13: 4.92 | D13: 22.51 | E13: ДТ 56 100, керосин 64 500 руб/т вместо 40 000 / 47 500
B14: Итог: наш вариант v4 | D14: =Расчёт_Наш!C5 -> 22.511796
B16: Выбор полки добычи (наш вариант, прочие параметры базовые)
B17: Полка, млрд м³/год | C17: NPV, млрд руб | D17: IRR | E17: CAPEX, млрд руб / скважин
B18: 8 | C18: 12.99 | D18: 0.1066 | E18: 279 / 38
B19: 9 | C19: 16.39 | D19: 0.1081 | E19: 300 / 43
B20: 10 | C20: 19.47 | D20: 0.1094 | E20: 321 / 48
B21: 11 | C21: 21.1 | D21: 0.11 | E21: 342 / 52
B22: 12 | C22: 22.51 | D22: 0.1104 | E22: 362 / 57
B23: 13 | C23: 22.94 | D23: 0.1105 | E23: 382 / 62
B24: 14 | C24: 22.28 | D24: 0.1101 | E24: 402 / 67
B26: Полка 12 выбрана: NPV практически равен максимуму (13 млрд м³), но CAPEX на 20 млрд руб меньше и отбор 3,75 % НГЗ в год соответствует практике Ямала.
B28: Чувствительность NPV нашего варианта (каждый фактор отдельно)
B29: Фактор | C29: NPV, хуже | D29: NPV, лучше | E29: Диапазон
B30: Цена газа −20 % / +20 % | C30: -27.93 | D30: 72.95 | E30: =D30-C30 -> 100.88
B31: CAPEX +20 % / −20 % | C31: -32.38 | D31: 77.21 | E31: =D31-C31 -> 109.59
B32: Дебит 0,55 / 0,95 млн м³/сут | C32: -1.55 | D32: 36.44 | E32: =D32-C32 -> 37.99
B33: Ставка 12 % / 8 % | C33: -17.35 | D33: 79.06 | E33: =D33-C33 -> 96.41
B34: Добыча −10 % / +10 % | C34: -5.9 | D34: 50.93 | E34: =D34-C34 -> 56.83
B35: Скважина 1,8 / 1,2 млрд руб | C35: 9.28 | D35: 35.75 | E35: =D35-C35 -> 26.47
B36: Brent 50 / 80 $/барр. | C36: 1.32 | D36: 43.7 | E36: =D36-C36 -> 42.38
B37: Цены ДТ и керосина −20 % / +20 % | C37: 18.95 | D37: 26.08 | E37: =D37-C37 -> 7.13
B39: Точки безубыточности (NPV = 0), наш вариант
B40: Параметр | C40: Порог | D40: База | E40: Запас
B41: Цена газа, руб/1000 м³ | C41: 4285.0445 | D41: 4705 | E41: =C41/D41-1 -> -0.089257279
B42: Дебит скважины, млн м³/сут | C42: 0.5596 | D42: 0.75 | E42: =C42/D42-1 -> -0.25386667
B43: Стоимость скважины, млрд руб | C43: 2.0103 | D43: 1.5 | E43: =C43/D43-1 -> 0.3402
B44: Ставка дисконтирования (= IRR) | C44: 0.1104 | D44: 0.1 | E44: =C44/D44-1 -> 0.104
B45: Множитель CAPEX | C45: 1.082 | D45: 1 | E45: =C45/D45-1 -> 0.082
B46: Brent, $/барр. | C46: 49.063 | D46: 65 | E46: =C46/D46-1 -> -0.24518462
...

Sheet Источники
B2: Источники данных
B3: Дата обращения — 24–25.10.2026, если не указано иное.
B5: Что взято | C5: Ссылка
B6: Оптовые цены на газ, ЯНАО (приказ ФАС № 1213/25) | C6: https://pravo.ppt.ru/prikaz/fas/n-1213-25-326387
B7: Ккг = 494 руб/1000 м³ для Газпрома с 01.10.2026 | C7: https://www.interfax.ru/business/1056714
